[2025-06-10T15:59:32.783+0000] {taskinstance.py:1956} INFO - Dependencies all met for dep_context=non-requeueable deps ti=<TaskInstance: data_ingestion_to_stg.load_customers_20180508 manual__2025-06-10T15:59:29.937624+00:00 [queued]>
[2025-06-10T15:59:32.799+0000] {taskinstance.py:1956} INFO - Dependencies all met for dep_context=requeueable deps ti=<TaskInstance: data_ingestion_to_stg.load_customers_20180508 manual__2025-06-10T15:59:29.937624+00:00 [queued]>
[2025-06-10T15:59:32.800+0000] {taskinstance.py:2170} INFO - Starting attempt 1 of 2
[2025-06-10T15:59:32.860+0000] {taskinstance.py:2191} INFO - Executing <Task(PythonOperator): load_customers_20180508> on 2025-06-10 15:59:29.937624+00:00
[2025-06-10T15:59:32.867+0000] {standard_task_runner.py:60} INFO - Started process 209 to run task
[2025-06-10T15:59:32.886+0000] {standard_task_runner.py:87} INFO - Running: ['***', 'tasks', 'run', 'data_ingestion_to_stg', 'load_customers_20180508', 'manual__2025-06-10T15:59:29.937624+00:00', '--job-id', '15', '--raw', '--subdir', 'DAGS_FOLDER/data_ingestion_to_stg.py', '--cfg-path', '/tmp/tmpu7ank8pn']
[2025-06-10T15:59:32.894+0000] {standard_task_runner.py:88} INFO - Job 15: Subtask load_customers_20180508
[2025-06-10T15:59:32.939+0000] {logging_mixin.py:188} WARNING - /home/***/.local/lib/python3.8/site-packages/***/settings.py:194 DeprecationWarning: The sql_alchemy_conn option in [core] has been moved to the sql_alchemy_conn option in [database] - the old setting has been used, but please update your config.
[2025-06-10T15:59:33.025+0000] {task_command.py:423} INFO - Running <TaskInstance: data_ingestion_to_stg.load_customers_20180508 manual__2025-06-10T15:59:29.937624+00:00 [running]> on host 382b107fa3ab
[2025-06-10T15:59:33.158+0000] {taskinstance.py:2480} INFO - Exporting env vars: AIRFLOW_CTX_DAG_OWNER='***' AIRFLOW_CTX_DAG_ID='data_ingestion_to_stg' AIRFLOW_CTX_TASK_ID='load_customers_20180508' AIRFLOW_CTX_EXECUTION_DATE='2025-06-10T15:59:29.937624+00:00' AIRFLOW_CTX_TRY_NUMBER='1' AIRFLOW_CTX_DAG_RUN_ID='manual__2025-06-10T15:59:29.937624+00:00'
[2025-06-10T15:59:33.163+0000] {taskinstance.py:2698} ERROR - Task failed with exception
Traceback (most recent call last):
  File "/home/airflow/.local/lib/python3.8/site-packages/airflow/models/taskinstance.py", line 433, in _execute_task
    result = execute_callable(context=context, **execute_callable_kwargs)
  File "/home/airflow/.local/lib/python3.8/site-packages/airflow/operators/python.py", line 199, in execute
    return_value = self.execute_callable()
  File "/home/airflow/.local/lib/python3.8/site-packages/airflow/operators/python.py", line 216, in execute_callable
    return self.python_callable(*self.op_args, **self.op_kwargs)
  File "/opt/airflow/dags/data_ingestion_to_stg.py", line 26, in load_csv_to_postgres
    raise FileNotFoundError(f"{file_path} tidak ditemukan.")
FileNotFoundError: /opt/***/INPUT/20180508/20180508.customers tidak ditemukan.
[2025-06-10T15:59:33.182+0000] {taskinstance.py:1138} INFO - Marking task as UP_FOR_RETRY. dag_id=data_ingestion_to_stg, task_id=load_customers_20180508, execution_date=20250610T155929, start_date=20250610T155932, end_date=20250610T155933
[2025-06-10T15:59:33.200+0000] {standard_task_runner.py:107} ERROR - Failed to execute job 15 for task load_customers_20180508 (/opt/***/INPUT/20180508/20180508.customers tidak ditemukan.; 209)
[2025-06-10T15:59:33.221+0000] {local_task_job_runner.py:234} INFO - Task exited with return code 1
[2025-06-10T15:59:33.405+0000] {taskinstance.py:3280} INFO - 0 downstream tasks scheduled from follow-on schedule check
