[2025-06-10T14:04:48.580+0000] {local_task_job_runner.py:123} INFO - ::group::Pre task execution logs
[2025-06-10T14:04:48.654+0000] {taskinstance.py:2612} INFO - Dependencies all met for dep_context=non-requeueable deps ti=<TaskInstance: data_ingestion_to_stg.load_sales_20180508 manual__2025-06-10T14:04:40.976039+00:00 [queued]>
[2025-06-10T14:04:48.678+0000] {taskinstance.py:2612} INFO - Dependencies all met for dep_context=requeueable deps ti=<TaskInstance: data_ingestion_to_stg.load_sales_20180508 manual__2025-06-10T14:04:40.976039+00:00 [queued]>
[2025-06-10T14:04:48.680+0000] {taskinstance.py:2865} INFO - Starting attempt 1 of 2
[2025-06-10T14:04:48.834+0000] {taskinstance.py:2888} INFO - Executing <Task(PythonOperator): load_sales_20180508> on 2025-06-10 14:04:40.976039+00:00
[2025-06-10T14:04:48.866+0000] {warnings.py:112} WARNING - /home/***/.local/lib/python3.12/site-packages/***/task/task_runner/standard_task_runner.py:70: DeprecationWarning: This process (pid=405) is multi-threaded, use of fork() may lead to deadlocks in the child.
  pid = os.fork()

[2025-06-10T14:04:48.875+0000] {standard_task_runner.py:72} INFO - Started process 429 to run task
[2025-06-10T14:04:48.922+0000] {standard_task_runner.py:104} INFO - Running: ['***', 'tasks', 'run', 'data_ingestion_to_stg', 'load_sales_20180508', 'manual__2025-06-10T14:04:40.976039+00:00', '--job-id', '110', '--raw', '--subdir', 'DAGS_FOLDER/data_ingestion_to_stg.py', '--cfg-path', '/tmp/tmpyu07jm0f']
[2025-06-10T14:04:48.927+0000] {standard_task_runner.py:105} INFO - Job 110: Subtask load_sales_20180508
[2025-06-10T14:04:49.193+0000] {task_command.py:467} INFO - Running <TaskInstance: data_ingestion_to_stg.load_sales_20180508 manual__2025-06-10T14:04:40.976039+00:00 [running]> on host 615918c75888
[2025-06-10T14:04:49.545+0000] {taskinstance.py:3131} INFO - Exporting env vars: AIRFLOW_CTX_DAG_OWNER='***' AIRFLOW_CTX_DAG_ID='data_ingestion_to_stg' AIRFLOW_CTX_TASK_ID='load_sales_20180508' AIRFLOW_CTX_EXECUTION_DATE='2025-06-10T14:04:40.976039+00:00' AIRFLOW_CTX_TRY_NUMBER='1' AIRFLOW_CTX_DAG_RUN_ID='manual__2025-06-10T14:04:40.976039+00:00'
[2025-06-10T14:04:49.558+0000] {logging_mixin.py:190} INFO - Task instance is in running state
[2025-06-10T14:04:49.559+0000] {logging_mixin.py:190} INFO -  Previous state of the Task instance: queued
[2025-06-10T14:04:49.560+0000] {logging_mixin.py:190} INFO - Current task name:load_sales_20180508 state:running start_date:2025-06-10 14:04:48.657022+00:00
[2025-06-10T14:04:49.561+0000] {logging_mixin.py:190} INFO - Dag name:data_ingestion_to_stg and current dag run status:running
[2025-06-10T14:04:49.562+0000] {taskinstance.py:731} INFO - ::endgroup::
[2025-06-10T14:04:49.566+0000] {taskinstance.py:3310} ERROR - Task failed with exception
Traceback (most recent call last):
  File "/home/airflow/.local/lib/python3.12/site-packages/airflow/models/taskinstance.py", line 767, in _execute_task
    result = _execute_callable(context=context, **execute_callable_kwargs)
             ^^^^^^^^^^^^^^^^^^^^^^^^^^^^^^^^^^^^^^^^^^^^^^^^^^^^^^^^^^^^^
  File "/home/airflow/.local/lib/python3.12/site-packages/airflow/models/taskinstance.py", line 733, in _execute_callable
    return ExecutionCallableRunner(
           ^^^^^^^^^^^^^^^^^^^^^^^^
  File "/home/airflow/.local/lib/python3.12/site-packages/airflow/utils/operator_helpers.py", line 252, in run
    return self.func(*args, **kwargs)
           ^^^^^^^^^^^^^^^^^^^^^^^^^^
  File "/home/airflow/.local/lib/python3.12/site-packages/airflow/models/baseoperator.py", line 406, in wrapper
    return func(self, *args, **kwargs)
           ^^^^^^^^^^^^^^^^^^^^^^^^^^^
  File "/home/airflow/.local/lib/python3.12/site-packages/airflow/operators/python.py", line 238, in execute
    return_value = self.execute_callable()
                   ^^^^^^^^^^^^^^^^^^^^^^^
  File "/home/airflow/.local/lib/python3.12/site-packages/airflow/operators/python.py", line 256, in execute_callable
    return runner.run(*self.op_args, **self.op_kwargs)
           ^^^^^^^^^^^^^^^^^^^^^^^^^^^^^^^^^^^^^^^^^^^
  File "/home/airflow/.local/lib/python3.12/site-packages/airflow/utils/operator_helpers.py", line 252, in run
    return self.func(*args, **kwargs)
           ^^^^^^^^^^^^^^^^^^^^^^^^^^
  File "/opt/airflow/dags/data_ingestion_to_stg.py", line 25, in load_csv_to_postgres
    raise FileNotFoundError(f"{file_path} tidak ditemukan.")
FileNotFoundError: C:/DNA/data-warehouse-project/INPUT/20180508/20180508.sales tidak ditemukan.
[2025-06-10T14:04:49.640+0000] {logging_mixin.py:190} INFO - Task instance in failure state
[2025-06-10T14:04:49.641+0000] {logging_mixin.py:190} INFO - Task start:2025-06-10 14:04:48.657022+00:00 end:2025-06-10 14:04:49.639048+00:00 duration:0.982026
[2025-06-10T14:04:49.644+0000] {logging_mixin.py:190} INFO - Task:<Task(PythonOperator): load_sales_20180508> dag:<DAG: data_ingestion_to_stg> dagrun:<DagRun data_ingestion_to_stg @ 2025-06-10 14:04:40.976039+00:00: manual__2025-06-10T14:04:40.976039+00:00, state:running, queued_at: 2025-06-10 14:04:40.996621+00:00. externally triggered: True>
[2025-06-10T14:04:49.652+0000] {logging_mixin.py:190} INFO - Failure caused by C:/DNA/data-warehouse-project/INPUT/20180508/20180508.sales tidak ditemukan.
[2025-06-10T14:04:49.654+0000] {taskinstance.py:1225} INFO - Marking task as UP_FOR_RETRY. dag_id=data_ingestion_to_stg, task_id=load_sales_20180508, run_id=manual__2025-06-10T14:04:40.976039+00:00, execution_date=20250610T140440, start_date=20250610T140448, end_date=20250610T140449
[2025-06-10T14:04:49.719+0000] {taskinstance.py:340} INFO - ::group::Post task execution logs
[2025-06-10T14:04:49.727+0000] {standard_task_runner.py:124} ERROR - Failed to execute job 110 for task load_sales_20180508 (C:/DNA/data-warehouse-project/INPUT/20180508/20180508.sales tidak ditemukan.; 429)
Traceback (most recent call last):
  File "/home/airflow/.local/lib/python3.12/site-packages/airflow/task/task_runner/standard_task_runner.py", line 117, in _start_by_fork
    ret = args.func(args, dag=self.dag)
          ^^^^^^^^^^^^^^^^^^^^^^^^^^^^^
  File "/home/airflow/.local/lib/python3.12/site-packages/airflow/cli/cli_config.py", line 49, in command
    return func(*args, **kwargs)
           ^^^^^^^^^^^^^^^^^^^^^
  File "/home/airflow/.local/lib/python3.12/site-packages/airflow/utils/cli.py", line 115, in wrapper
    return f(*args, **kwargs)
           ^^^^^^^^^^^^^^^^^^
  File "/home/airflow/.local/lib/python3.12/site-packages/airflow/cli/commands/task_command.py", line 483, in task_run
    task_return_code = _run_task_by_selected_method(args, _dag, ti)
                       ^^^^^^^^^^^^^^^^^^^^^^^^^^^^^^^^^^^^^^^^^^^^
  File "/home/airflow/.local/lib/python3.12/site-packages/airflow/cli/commands/task_command.py", line 256, in _run_task_by_selected_method
    return _run_raw_task(args, ti)
           ^^^^^^^^^^^^^^^^^^^^^^^
  File "/home/airflow/.local/lib/python3.12/site-packages/airflow/cli/commands/task_command.py", line 341, in _run_raw_task
    return ti._run_raw_task(
           ^^^^^^^^^^^^^^^^^
  File "/home/airflow/.local/lib/python3.12/site-packages/airflow/utils/session.py", line 97, in wrapper
    return func(*args, session=session, **kwargs)
           ^^^^^^^^^^^^^^^^^^^^^^^^^^^^^^^^^^^^^^
  File "/home/airflow/.local/lib/python3.12/site-packages/airflow/models/taskinstance.py", line 3004, in _run_raw_task
    return _run_raw_task(
           ^^^^^^^^^^^^^^
  File "/home/airflow/.local/lib/python3.12/site-packages/airflow/models/taskinstance.py", line 273, in _run_raw_task
    TaskInstance._execute_task_with_callbacks(
  File "/home/airflow/.local/lib/python3.12/site-packages/airflow/models/taskinstance.py", line 3158, in _execute_task_with_callbacks
    result = self._execute_task(context, task_orig)
             ^^^^^^^^^^^^^^^^^^^^^^^^^^^^^^^^^^^^^^
  File "/home/airflow/.local/lib/python3.12/site-packages/airflow/models/taskinstance.py", line 3182, in _execute_task
    return _execute_task(self, context, task_orig)
           ^^^^^^^^^^^^^^^^^^^^^^^^^^^^^^^^^^^^^^^
  File "/home/airflow/.local/lib/python3.12/site-packages/airflow/models/taskinstance.py", line 767, in _execute_task
    result = _execute_callable(context=context, **execute_callable_kwargs)
             ^^^^^^^^^^^^^^^^^^^^^^^^^^^^^^^^^^^^^^^^^^^^^^^^^^^^^^^^^^^^^
  File "/home/airflow/.local/lib/python3.12/site-packages/airflow/models/taskinstance.py", line 733, in _execute_callable
    return ExecutionCallableRunner(
           ^^^^^^^^^^^^^^^^^^^^^^^^
  File "/home/airflow/.local/lib/python3.12/site-packages/airflow/utils/operator_helpers.py", line 252, in run
    return self.func(*args, **kwargs)
           ^^^^^^^^^^^^^^^^^^^^^^^^^^
  File "/home/airflow/.local/lib/python3.12/site-packages/airflow/models/baseoperator.py", line 406, in wrapper
    return func(self, *args, **kwargs)
           ^^^^^^^^^^^^^^^^^^^^^^^^^^^
  File "/home/airflow/.local/lib/python3.12/site-packages/airflow/operators/python.py", line 238, in execute
    return_value = self.execute_callable()
                   ^^^^^^^^^^^^^^^^^^^^^^^
  File "/home/airflow/.local/lib/python3.12/site-packages/airflow/operators/python.py", line 256, in execute_callable
    return runner.run(*self.op_args, **self.op_kwargs)
           ^^^^^^^^^^^^^^^^^^^^^^^^^^^^^^^^^^^^^^^^^^^
  File "/home/airflow/.local/lib/python3.12/site-packages/airflow/utils/operator_helpers.py", line 252, in run
    return self.func(*args, **kwargs)
           ^^^^^^^^^^^^^^^^^^^^^^^^^^
  File "/opt/airflow/dags/data_ingestion_to_stg.py", line 25, in load_csv_to_postgres
    raise FileNotFoundError(f"{file_path} tidak ditemukan.")
FileNotFoundError: C:/DNA/data-warehouse-project/INPUT/20180508/20180508.sales tidak ditemukan.
[2025-06-10T14:04:49.806+0000] {local_task_job_runner.py:266} INFO - Task exited with return code 1
[2025-06-10T14:04:49.943+0000] {taskinstance.py:3900} INFO - 0 downstream tasks scheduled from follow-on schedule check
[2025-06-10T14:04:49.961+0000] {local_task_job_runner.py:245} INFO - ::endgroup::
