[2025-06-10T16:10:56.910+0000] {taskinstance.py:1956} INFO - Dependencies all met for dep_context=non-requeueable deps ti=<TaskInstance: data_ingestion_to_stg.load_sales_20180509 manual__2025-06-10T16:10:55.391786+00:00 [queued]>
[2025-06-10T16:10:56.938+0000] {taskinstance.py:1956} INFO - Dependencies all met for dep_context=requeueable deps ti=<TaskInstance: data_ingestion_to_stg.load_sales_20180509 manual__2025-06-10T16:10:55.391786+00:00 [queued]>
[2025-06-10T16:10:56.939+0000] {taskinstance.py:2170} INFO - Starting attempt 1 of 2
[2025-06-10T16:10:56.970+0000] {taskinstance.py:2191} INFO - Executing <Task(PythonOperator): load_sales_20180509> on 2025-06-10 16:10:55.391786+00:00
[2025-06-10T16:10:56.978+0000] {standard_task_runner.py:60} INFO - Started process 411 to run task
[2025-06-10T16:10:56.984+0000] {standard_task_runner.py:87} INFO - Running: ['***', 'tasks', 'run', 'data_ingestion_to_stg', 'load_sales_20180509', 'manual__2025-06-10T16:10:55.391786+00:00', '--job-id', '53', '--raw', '--subdir', 'DAGS_FOLDER/data_ingestion_to_stg.py', '--cfg-path', '/tmp/tmp7m1bwmvd']
[2025-06-10T16:10:56.992+0000] {standard_task_runner.py:88} INFO - Job 53: Subtask load_sales_20180509
[2025-06-10T16:10:57.042+0000] {logging_mixin.py:188} WARNING - /home/***/.local/lib/python3.8/site-packages/***/settings.py:194 DeprecationWarning: The sql_alchemy_conn option in [core] has been moved to the sql_alchemy_conn option in [database] - the old setting has been used, but please update your config.
[2025-06-10T16:10:57.127+0000] {task_command.py:423} INFO - Running <TaskInstance: data_ingestion_to_stg.load_sales_20180509 manual__2025-06-10T16:10:55.391786+00:00 [running]> on host 382b107fa3ab
[2025-06-10T16:10:57.311+0000] {taskinstance.py:2480} INFO - Exporting env vars: AIRFLOW_CTX_DAG_OWNER='***' AIRFLOW_CTX_DAG_ID='data_ingestion_to_stg' AIRFLOW_CTX_TASK_ID='load_sales_20180509' AIRFLOW_CTX_EXECUTION_DATE='2025-06-10T16:10:55.391786+00:00' AIRFLOW_CTX_TRY_NUMBER='1' AIRFLOW_CTX_DAG_RUN_ID='manual__2025-06-10T16:10:55.391786+00:00'
[2025-06-10T16:10:57.330+0000] {postgres.py:172} INFO - Running copy expert: COPY stg.sales FROM STDIN WITH CSV DELIMITER ';' HEADER, filename: /opt/***/INPUT/20180509/20180509.sales.csv
[2025-06-10T16:10:57.356+0000] {base.py:83} INFO - Using connection ID 'data-warehouse-project' for task execution.
[2025-06-10T16:10:57.360+0000] {taskinstance.py:2698} ERROR - Task failed with exception
Traceback (most recent call last):
  File "/home/airflow/.local/lib/python3.8/site-packages/airflow/models/taskinstance.py", line 433, in _execute_task
    result = execute_callable(context=context, **execute_callable_kwargs)
  File "/home/airflow/.local/lib/python3.8/site-packages/airflow/operators/python.py", line 199, in execute
    return_value = self.execute_callable()
  File "/home/airflow/.local/lib/python3.8/site-packages/airflow/operators/python.py", line 216, in execute_callable
    return self.python_callable(*self.op_args, **self.op_kwargs)
  File "/opt/airflow/dags/data_ingestion_to_stg.py", line 29, in load_csv_to_postgres
    pg_hook.copy_expert(
  File "/home/airflow/.local/lib/python3.8/site-packages/airflow/providers/postgres/hooks/postgres.py", line 177, in copy_expert
    with open(filename, "r+") as file, closing(self.get_conn()) as conn, closing(conn.cursor()) as cur:
  File "/home/airflow/.local/lib/python3.8/site-packages/airflow/providers/postgres/hooks/postgres.py", line 158, in get_conn
    self.conn = psycopg2.connect(**conn_args)
  File "/home/airflow/.local/lib/python3.8/site-packages/psycopg2/__init__.py", line 122, in connect
    conn = _connect(dsn, connection_factory=connection_factory, **kwasync)
psycopg2.OperationalError: connection to server at "localhost" (::1), port 5432 failed: Connection refused
	Is the server running on that host and accepting TCP/IP connections?
connection to server at "localhost" (127.0.0.1), port 5432 failed: Connection refused
	Is the server running on that host and accepting TCP/IP connections?

[2025-06-10T16:10:57.389+0000] {taskinstance.py:1138} INFO - Marking task as UP_FOR_RETRY. dag_id=data_ingestion_to_stg, task_id=load_sales_20180509, execution_date=20250610T161055, start_date=20250610T161056, end_date=20250610T161057
[2025-06-10T16:10:57.425+0000] {standard_task_runner.py:107} ERROR - Failed to execute job 53 for task load_sales_20180509 (connection to server at "localhost" (::1), port 5432 failed: Connection refused
	Is the server running on that host and accepting TCP/IP connections?
connection to server at "localhost" (127.0.0.1), port 5432 failed: Connection refused
	Is the server running on that host and accepting TCP/IP connections?
; 411)
[2025-06-10T16:10:57.464+0000] {local_task_job_runner.py:234} INFO - Task exited with return code 1
[2025-06-10T16:10:57.684+0000] {taskinstance.py:3280} INFO - 0 downstream tasks scheduled from follow-on schedule check
