[2025-06-10T16:07:48.452+0000] {taskinstance.py:1956} INFO - Dependencies all met for dep_context=non-requeueable deps ti=<TaskInstance: data_ingestion_to_stg.load_sales_20180508 manual__2025-06-10T16:07:46.625257+00:00 [queued]>
[2025-06-10T16:07:48.486+0000] {taskinstance.py:1956} INFO - Dependencies all met for dep_context=requeueable deps ti=<TaskInstance: data_ingestion_to_stg.load_sales_20180508 manual__2025-06-10T16:07:46.625257+00:00 [queued]>
[2025-06-10T16:07:48.487+0000] {taskinstance.py:2170} INFO - Starting attempt 1 of 2
[2025-06-10T16:07:48.532+0000] {taskinstance.py:2191} INFO - Executing <Task(PythonOperator): load_sales_20180508> on 2025-06-10 16:07:46.625257+00:00
[2025-06-10T16:07:48.537+0000] {standard_task_runner.py:60} INFO - Started process 343 to run task
[2025-06-10T16:07:48.556+0000] {standard_task_runner.py:87} INFO - Running: ['***', 'tasks', 'run', 'data_ingestion_to_stg', 'load_sales_20180508', 'manual__2025-06-10T16:07:46.625257+00:00', '--job-id', '32', '--raw', '--subdir', 'DAGS_FOLDER/data_ingestion_to_stg.py', '--cfg-path', '/tmp/tmpy3g57s_j']
[2025-06-10T16:07:48.575+0000] {standard_task_runner.py:88} INFO - Job 32: Subtask load_sales_20180508
[2025-06-10T16:07:48.618+0000] {logging_mixin.py:188} WARNING - /home/***/.local/lib/python3.8/site-packages/***/settings.py:194 DeprecationWarning: The sql_alchemy_conn option in [core] has been moved to the sql_alchemy_conn option in [database] - the old setting has been used, but please update your config.
[2025-06-10T16:07:48.706+0000] {task_command.py:423} INFO - Running <TaskInstance: data_ingestion_to_stg.load_sales_20180508 manual__2025-06-10T16:07:46.625257+00:00 [running]> on host 382b107fa3ab
[2025-06-10T16:07:48.913+0000] {taskinstance.py:2480} INFO - Exporting env vars: AIRFLOW_CTX_DAG_OWNER='***' AIRFLOW_CTX_DAG_ID='data_ingestion_to_stg' AIRFLOW_CTX_TASK_ID='load_sales_20180508' AIRFLOW_CTX_EXECUTION_DATE='2025-06-10T16:07:46.625257+00:00' AIRFLOW_CTX_TRY_NUMBER='1' AIRFLOW_CTX_DAG_RUN_ID='manual__2025-06-10T16:07:46.625257+00:00'
[2025-06-10T16:07:48.922+0000] {postgres.py:172} INFO - Running copy expert: COPY stg.sales FROM STDIN WITH CSV DELIMITER ';' HEADER, filename: /opt/***/INPUT/20180508/20180508.sales.csv
[2025-06-10T16:07:48.990+0000] {taskinstance.py:2698} ERROR - Task failed with exception
Traceback (most recent call last):
  File "/home/airflow/.local/lib/python3.8/site-packages/airflow/models/taskinstance.py", line 433, in _execute_task
    result = execute_callable(context=context, **execute_callable_kwargs)
  File "/home/airflow/.local/lib/python3.8/site-packages/airflow/operators/python.py", line 199, in execute
    return_value = self.execute_callable()
  File "/home/airflow/.local/lib/python3.8/site-packages/airflow/operators/python.py", line 216, in execute_callable
    return self.python_callable(*self.op_args, **self.op_kwargs)
  File "/opt/airflow/dags/data_ingestion_to_stg.py", line 29, in load_csv_to_postgres
    pg_hook.copy_expert(
  File "/home/airflow/.local/lib/python3.8/site-packages/airflow/providers/postgres/hooks/postgres.py", line 177, in copy_expert
    with open(filename, "r+") as file, closing(self.get_conn()) as conn, closing(conn.cursor()) as cur:
  File "/home/airflow/.local/lib/python3.8/site-packages/airflow/providers/postgres/hooks/postgres.py", line 128, in get_conn
    conn = deepcopy(self.connection or self.get_connection(conn_id))
  File "/home/airflow/.local/lib/python3.8/site-packages/airflow/hooks/base.py", line 82, in get_connection
    conn = Connection.get_connection_from_secrets(conn_id)
  File "/home/airflow/.local/lib/python3.8/site-packages/airflow/models/connection.py", line 479, in get_connection_from_secrets
    raise AirflowNotFoundException(f"The conn_id `{conn_id}` isn't defined")
airflow.exceptions.AirflowNotFoundException: The conn_id `data-warehouse-project` isn't defined
[2025-06-10T16:07:49.001+0000] {taskinstance.py:1138} INFO - Marking task as UP_FOR_RETRY. dag_id=data_ingestion_to_stg, task_id=load_sales_20180508, execution_date=20250610T160746, start_date=20250610T160748, end_date=20250610T160749
[2025-06-10T16:07:49.090+0000] {standard_task_runner.py:107} ERROR - Failed to execute job 32 for task load_sales_20180508 (The conn_id `data-warehouse-project` isn't defined; 343)
[2025-06-10T16:07:49.127+0000] {local_task_job_runner.py:234} INFO - Task exited with return code 1
[2025-06-10T16:07:49.318+0000] {taskinstance.py:3280} INFO - 0 downstream tasks scheduled from follow-on schedule check
