[2025-06-10T15:00:40.505+0000] {local_task_job_runner.py:123} INFO - ::group::Pre task execution logs
[2025-06-10T15:00:40.584+0000] {taskinstance.py:2612} INFO - Dependencies all met for dep_context=non-requeueable deps ti=<TaskInstance: data_ingestion_to_stg.load_customers_20180509 manual__2025-06-10T14:54:31.899863+00:00 [queued]>
[2025-06-10T15:00:40.615+0000] {taskinstance.py:2612} INFO - Dependencies all met for dep_context=requeueable deps ti=<TaskInstance: data_ingestion_to_stg.load_customers_20180509 manual__2025-06-10T14:54:31.899863+00:00 [queued]>
[2025-06-10T15:00:40.617+0000] {taskinstance.py:2865} INFO - Starting attempt 2 of 2
[2025-06-10T15:00:40.767+0000] {taskinstance.py:2888} INFO - Executing <Task(PythonOperator): load_customers_20180509> on 2025-06-10 14:54:31.899863+00:00
[2025-06-10T15:00:40.797+0000] {warnings.py:112} WARNING - /home/***/.local/lib/python3.12/site-packages/***/task/task_runner/standard_task_runner.py:70: DeprecationWarning: This process (pid=68) is multi-threaded, use of fork() may lead to deadlocks in the child.
  pid = os.fork()

[2025-06-10T15:00:40.806+0000] {standard_task_runner.py:72} INFO - Started process 100 to run task
[2025-06-10T15:00:40.829+0000] {standard_task_runner.py:104} INFO - Running: ['***', 'tasks', 'run', 'data_ingestion_to_stg', 'load_customers_20180509', 'manual__2025-06-10T14:54:31.899863+00:00', '--job-id', '261', '--raw', '--subdir', 'DAGS_FOLDER/data_ingestion_to_stg.py', '--cfg-path', '/tmp/tmper931c48']
[2025-06-10T15:00:40.840+0000] {standard_task_runner.py:105} INFO - Job 261: Subtask load_customers_20180509
[2025-06-10T15:00:41.092+0000] {task_command.py:467} INFO - Running <TaskInstance: data_ingestion_to_stg.load_customers_20180509 manual__2025-06-10T14:54:31.899863+00:00 [running]> on host 2602e9baa8a6
[2025-06-10T15:00:41.901+0000] {taskinstance.py:3131} INFO - Exporting env vars: AIRFLOW_CTX_DAG_OWNER='***' AIRFLOW_CTX_DAG_ID='data_ingestion_to_stg' AIRFLOW_CTX_TASK_ID='load_customers_20180509' AIRFLOW_CTX_EXECUTION_DATE='2025-06-10T14:54:31.899863+00:00' AIRFLOW_CTX_TRY_NUMBER='2' AIRFLOW_CTX_DAG_RUN_ID='manual__2025-06-10T14:54:31.899863+00:00'
[2025-06-10T15:00:41.905+0000] {logging_mixin.py:190} INFO - Task instance is in running state
[2025-06-10T15:00:41.906+0000] {logging_mixin.py:190} INFO -  Previous state of the Task instance: queued
[2025-06-10T15:00:41.908+0000] {logging_mixin.py:190} INFO - Current task name:load_customers_20180509 state:running start_date:2025-06-10 15:00:40.585303+00:00
[2025-06-10T15:00:41.908+0000] {logging_mixin.py:190} INFO - Dag name:data_ingestion_to_stg and current dag run status:running
[2025-06-10T15:00:41.911+0000] {taskinstance.py:731} INFO - ::endgroup::
[2025-06-10T15:00:41.915+0000] {taskinstance.py:3310} ERROR - Task failed with exception
Traceback (most recent call last):
  File "/home/airflow/.local/lib/python3.12/site-packages/airflow/models/taskinstance.py", line 767, in _execute_task
    result = _execute_callable(context=context, **execute_callable_kwargs)
             ^^^^^^^^^^^^^^^^^^^^^^^^^^^^^^^^^^^^^^^^^^^^^^^^^^^^^^^^^^^^^
  File "/home/airflow/.local/lib/python3.12/site-packages/airflow/models/taskinstance.py", line 733, in _execute_callable
    return ExecutionCallableRunner(
           ^^^^^^^^^^^^^^^^^^^^^^^^
  File "/home/airflow/.local/lib/python3.12/site-packages/airflow/utils/operator_helpers.py", line 252, in run
    return self.func(*args, **kwargs)
           ^^^^^^^^^^^^^^^^^^^^^^^^^^
  File "/home/airflow/.local/lib/python3.12/site-packages/airflow/models/baseoperator.py", line 406, in wrapper
    return func(self, *args, **kwargs)
           ^^^^^^^^^^^^^^^^^^^^^^^^^^^
  File "/home/airflow/.local/lib/python3.12/site-packages/airflow/operators/python.py", line 238, in execute
    return_value = self.execute_callable()
                   ^^^^^^^^^^^^^^^^^^^^^^^
  File "/home/airflow/.local/lib/python3.12/site-packages/airflow/operators/python.py", line 256, in execute_callable
    return runner.run(*self.op_args, **self.op_kwargs)
           ^^^^^^^^^^^^^^^^^^^^^^^^^^^^^^^^^^^^^^^^^^^
  File "/home/airflow/.local/lib/python3.12/site-packages/airflow/utils/operator_helpers.py", line 252, in run
    return self.func(*args, **kwargs)
           ^^^^^^^^^^^^^^^^^^^^^^^^^^
  File "/opt/airflow/dags/data_ingestion_to_stg.py", line 25, in load_csv_to_postgres
    raise FileNotFoundError(f"{file_path} tidak ditemukan.")
FileNotFoundError: /opt/***/dags/data/20180509/20180509.customers tidak ditemukan.
[2025-06-10T15:00:42.060+0000] {logging_mixin.py:190} INFO - Task instance in failure state
[2025-06-10T15:00:42.079+0000] {logging_mixin.py:190} INFO - Task start:2025-06-10 15:00:40.585303+00:00 end:2025-06-10 15:00:42.053604+00:00 duration:1.468301
[2025-06-10T15:00:42.089+0000] {logging_mixin.py:190} INFO - Task:<Task(PythonOperator): load_customers_20180509> dag:<DAG: data_ingestion_to_stg> dagrun:<DagRun data_ingestion_to_stg @ 2025-06-10 14:54:31.899863+00:00: manual__2025-06-10T14:54:31.899863+00:00, state:running, queued_at: 2025-06-10 14:54:31.999708+00:00. externally triggered: True>
[2025-06-10T15:00:42.091+0000] {logging_mixin.py:190} INFO - Failure caused by /opt/***/dags/data/20180509/20180509.customers tidak ditemukan.
[2025-06-10T15:00:42.094+0000] {taskinstance.py:1225} INFO - Marking task as FAILED. dag_id=data_ingestion_to_stg, task_id=load_customers_20180509, run_id=manual__2025-06-10T14:54:31.899863+00:00, execution_date=20250610T145431, start_date=20250610T150040, end_date=20250610T150042
[2025-06-10T15:00:42.264+0000] {taskinstance.py:340} INFO - ::group::Post task execution logs
[2025-06-10T15:00:42.266+0000] {standard_task_runner.py:124} ERROR - Failed to execute job 261 for task load_customers_20180509 (/opt/***/dags/data/20180509/20180509.customers tidak ditemukan.; 100)
Traceback (most recent call last):
  File "/home/airflow/.local/lib/python3.12/site-packages/airflow/task/task_runner/standard_task_runner.py", line 117, in _start_by_fork
    ret = args.func(args, dag=self.dag)
          ^^^^^^^^^^^^^^^^^^^^^^^^^^^^^
  File "/home/airflow/.local/lib/python3.12/site-packages/airflow/cli/cli_config.py", line 49, in command
    return func(*args, **kwargs)
           ^^^^^^^^^^^^^^^^^^^^^
  File "/home/airflow/.local/lib/python3.12/site-packages/airflow/utils/cli.py", line 115, in wrapper
    return f(*args, **kwargs)
           ^^^^^^^^^^^^^^^^^^
  File "/home/airflow/.local/lib/python3.12/site-packages/airflow/cli/commands/task_command.py", line 483, in task_run
    task_return_code = _run_task_by_selected_method(args, _dag, ti)
                       ^^^^^^^^^^^^^^^^^^^^^^^^^^^^^^^^^^^^^^^^^^^^
  File "/home/airflow/.local/lib/python3.12/site-packages/airflow/cli/commands/task_command.py", line 256, in _run_task_by_selected_method
    return _run_raw_task(args, ti)
           ^^^^^^^^^^^^^^^^^^^^^^^
  File "/home/airflow/.local/lib/python3.12/site-packages/airflow/cli/commands/task_command.py", line 341, in _run_raw_task
    return ti._run_raw_task(
           ^^^^^^^^^^^^^^^^^
  File "/home/airflow/.local/lib/python3.12/site-packages/airflow/utils/session.py", line 97, in wrapper
    return func(*args, session=session, **kwargs)
           ^^^^^^^^^^^^^^^^^^^^^^^^^^^^^^^^^^^^^^
  File "/home/airflow/.local/lib/python3.12/site-packages/airflow/models/taskinstance.py", line 3004, in _run_raw_task
    return _run_raw_task(
           ^^^^^^^^^^^^^^
  File "/home/airflow/.local/lib/python3.12/site-packages/airflow/models/taskinstance.py", line 273, in _run_raw_task
    TaskInstance._execute_task_with_callbacks(
  File "/home/airflow/.local/lib/python3.12/site-packages/airflow/models/taskinstance.py", line 3158, in _execute_task_with_callbacks
    result = self._execute_task(context, task_orig)
             ^^^^^^^^^^^^^^^^^^^^^^^^^^^^^^^^^^^^^^
  File "/home/airflow/.local/lib/python3.12/site-packages/airflow/models/taskinstance.py", line 3182, in _execute_task
    return _execute_task(self, context, task_orig)
           ^^^^^^^^^^^^^^^^^^^^^^^^^^^^^^^^^^^^^^^
  File "/home/airflow/.local/lib/python3.12/site-packages/airflow/models/taskinstance.py", line 767, in _execute_task
    result = _execute_callable(context=context, **execute_callable_kwargs)
             ^^^^^^^^^^^^^^^^^^^^^^^^^^^^^^^^^^^^^^^^^^^^^^^^^^^^^^^^^^^^^
  File "/home/airflow/.local/lib/python3.12/site-packages/airflow/models/taskinstance.py", line 733, in _execute_callable
    return ExecutionCallableRunner(
           ^^^^^^^^^^^^^^^^^^^^^^^^
  File "/home/airflow/.local/lib/python3.12/site-packages/airflow/utils/operator_helpers.py", line 252, in run
    return self.func(*args, **kwargs)
           ^^^^^^^^^^^^^^^^^^^^^^^^^^
  File "/home/airflow/.local/lib/python3.12/site-packages/airflow/models/baseoperator.py", line 406, in wrapper
    return func(self, *args, **kwargs)
           ^^^^^^^^^^^^^^^^^^^^^^^^^^^
  File "/home/airflow/.local/lib/python3.12/site-packages/airflow/operators/python.py", line 238, in execute
    return_value = self.execute_callable()
                   ^^^^^^^^^^^^^^^^^^^^^^^
  File "/home/airflow/.local/lib/python3.12/site-packages/airflow/operators/python.py", line 256, in execute_callable
    return runner.run(*self.op_args, **self.op_kwargs)
           ^^^^^^^^^^^^^^^^^^^^^^^^^^^^^^^^^^^^^^^^^^^
  File "/home/airflow/.local/lib/python3.12/site-packages/airflow/utils/operator_helpers.py", line 252, in run
    return self.func(*args, **kwargs)
           ^^^^^^^^^^^^^^^^^^^^^^^^^^
  File "/opt/airflow/dags/data_ingestion_to_stg.py", line 25, in load_csv_to_postgres
    raise FileNotFoundError(f"{file_path} tidak ditemukan.")
FileNotFoundError: /opt/***/dags/data/20180509/20180509.customers tidak ditemukan.
[2025-06-10T15:00:42.396+0000] {local_task_job_runner.py:266} INFO - Task exited with return code 1
[2025-06-10T15:00:42.475+0000] {taskinstance.py:3900} INFO - 0 downstream tasks scheduled from follow-on schedule check
[2025-06-10T15:00:42.481+0000] {local_task_job_runner.py:245} INFO - ::endgroup::
