[2025-06-10T14:51:04.315+0000] {local_task_job_runner.py:123} INFO - ::group::Pre task execution logs
[2025-06-10T14:51:04.414+0000] {taskinstance.py:2612} INFO - Dependencies all met for dep_context=non-requeueable deps ti=<TaskInstance: data_ingestion_to_stg.load_sales_20180509 manual__2025-06-10T14:45:44.077258+00:00 [queued]>
[2025-06-10T14:51:04.456+0000] {taskinstance.py:2612} INFO - Dependencies all met for dep_context=requeueable deps ti=<TaskInstance: data_ingestion_to_stg.load_sales_20180509 manual__2025-06-10T14:45:44.077258+00:00 [queued]>
[2025-06-10T14:51:04.458+0000] {taskinstance.py:2865} INFO - Starting attempt 2 of 2
[2025-06-10T14:51:04.513+0000] {taskinstance.py:2888} INFO - Executing <Task(PythonOperator): load_sales_20180509> on 2025-06-10 14:45:44.077258+00:00
[2025-06-10T14:51:04.537+0000] {warnings.py:112} WARNING - /home/***/.local/lib/python3.12/site-packages/***/task/task_runner/standard_task_runner.py:70: DeprecationWarning: This process (pid=496) is multi-threaded, use of fork() may lead to deadlocks in the child.
  pid = os.fork()

[2025-06-10T14:51:04.541+0000] {standard_task_runner.py:104} INFO - Running: ['***', 'tasks', 'run', 'data_ingestion_to_stg', 'load_sales_20180509', 'manual__2025-06-10T14:45:44.077258+00:00', '--job-id', '233', '--raw', '--subdir', 'DAGS_FOLDER/data_ingestion_to_stg.py', '--cfg-path', '/tmp/tmp6j8mg932']
[2025-06-10T14:51:04.551+0000] {standard_task_runner.py:105} INFO - Job 233: Subtask load_sales_20180509
[2025-06-10T14:51:04.550+0000] {standard_task_runner.py:72} INFO - Started process 540 to run task
[2025-06-10T14:51:04.783+0000] {task_command.py:467} INFO - Running <TaskInstance: data_ingestion_to_stg.load_sales_20180509 manual__2025-06-10T14:45:44.077258+00:00 [running]> on host 548b6c6a89dc
[2025-06-10T14:51:05.088+0000] {taskinstance.py:3131} INFO - Exporting env vars: AIRFLOW_CTX_DAG_OWNER='***' AIRFLOW_CTX_DAG_ID='data_ingestion_to_stg' AIRFLOW_CTX_TASK_ID='load_sales_20180509' AIRFLOW_CTX_EXECUTION_DATE='2025-06-10T14:45:44.077258+00:00' AIRFLOW_CTX_TRY_NUMBER='2' AIRFLOW_CTX_DAG_RUN_ID='manual__2025-06-10T14:45:44.077258+00:00'
[2025-06-10T14:51:05.096+0000] {logging_mixin.py:190} INFO - Task instance is in running state
[2025-06-10T14:51:05.099+0000] {logging_mixin.py:190} INFO -  Previous state of the Task instance: queued
[2025-06-10T14:51:05.101+0000] {logging_mixin.py:190} INFO - Current task name:load_sales_20180509 state:running start_date:2025-06-10 14:51:04.419664+00:00
[2025-06-10T14:51:05.102+0000] {logging_mixin.py:190} INFO - Dag name:data_ingestion_to_stg and current dag run status:running
[2025-06-10T14:51:05.104+0000] {taskinstance.py:731} INFO - ::endgroup::
[2025-06-10T14:51:05.113+0000] {taskinstance.py:3310} ERROR - Task failed with exception
Traceback (most recent call last):
  File "/home/airflow/.local/lib/python3.12/site-packages/airflow/models/taskinstance.py", line 767, in _execute_task
    result = _execute_callable(context=context, **execute_callable_kwargs)
             ^^^^^^^^^^^^^^^^^^^^^^^^^^^^^^^^^^^^^^^^^^^^^^^^^^^^^^^^^^^^^
  File "/home/airflow/.local/lib/python3.12/site-packages/airflow/models/taskinstance.py", line 733, in _execute_callable
    return ExecutionCallableRunner(
           ^^^^^^^^^^^^^^^^^^^^^^^^
  File "/home/airflow/.local/lib/python3.12/site-packages/airflow/utils/operator_helpers.py", line 252, in run
    return self.func(*args, **kwargs)
           ^^^^^^^^^^^^^^^^^^^^^^^^^^
  File "/home/airflow/.local/lib/python3.12/site-packages/airflow/models/baseoperator.py", line 406, in wrapper
    return func(self, *args, **kwargs)
           ^^^^^^^^^^^^^^^^^^^^^^^^^^^
  File "/home/airflow/.local/lib/python3.12/site-packages/airflow/operators/python.py", line 238, in execute
    return_value = self.execute_callable()
                   ^^^^^^^^^^^^^^^^^^^^^^^
  File "/home/airflow/.local/lib/python3.12/site-packages/airflow/operators/python.py", line 256, in execute_callable
    return runner.run(*self.op_args, **self.op_kwargs)
           ^^^^^^^^^^^^^^^^^^^^^^^^^^^^^^^^^^^^^^^^^^^
  File "/home/airflow/.local/lib/python3.12/site-packages/airflow/utils/operator_helpers.py", line 252, in run
    return self.func(*args, **kwargs)
           ^^^^^^^^^^^^^^^^^^^^^^^^^^
  File "/opt/airflow/dags/data_ingestion_to_stg.py", line 25, in load_csv_to_postgres
    raise FileNotFoundError(f"{file_path} tidak ditemukan.")
FileNotFoundError: /opt/***/INPUT/20180509/20180509.sales tidak ditemukan.
[2025-06-10T14:51:05.159+0000] {logging_mixin.py:190} INFO - Task instance in failure state
[2025-06-10T14:51:05.161+0000] {logging_mixin.py:190} INFO - Task start:2025-06-10 14:51:04.419664+00:00 end:2025-06-10 14:51:05.158418+00:00 duration:0.738754
[2025-06-10T14:51:05.171+0000] {logging_mixin.py:190} INFO - Task:<Task(PythonOperator): load_sales_20180509> dag:<DAG: data_ingestion_to_stg> dagrun:<DagRun data_ingestion_to_stg @ 2025-06-10 14:45:44.077258+00:00: manual__2025-06-10T14:45:44.077258+00:00, state:running, queued_at: 2025-06-10 14:45:44.105301+00:00. externally triggered: True>
[2025-06-10T14:51:05.180+0000] {logging_mixin.py:190} INFO - Failure caused by /opt/***/INPUT/20180509/20180509.sales tidak ditemukan.
[2025-06-10T14:51:05.188+0000] {taskinstance.py:1225} INFO - Marking task as FAILED. dag_id=data_ingestion_to_stg, task_id=load_sales_20180509, run_id=manual__2025-06-10T14:45:44.077258+00:00, execution_date=20250610T144544, start_date=20250610T145104, end_date=20250610T145105
[2025-06-10T14:51:05.243+0000] {taskinstance.py:340} INFO - ::group::Post task execution logs
[2025-06-10T14:51:05.249+0000] {standard_task_runner.py:124} ERROR - Failed to execute job 233 for task load_sales_20180509 (/opt/***/INPUT/20180509/20180509.sales tidak ditemukan.; 540)
Traceback (most recent call last):
  File "/home/airflow/.local/lib/python3.12/site-packages/airflow/task/task_runner/standard_task_runner.py", line 117, in _start_by_fork
    ret = args.func(args, dag=self.dag)
          ^^^^^^^^^^^^^^^^^^^^^^^^^^^^^
  File "/home/airflow/.local/lib/python3.12/site-packages/airflow/cli/cli_config.py", line 49, in command
    return func(*args, **kwargs)
           ^^^^^^^^^^^^^^^^^^^^^
  File "/home/airflow/.local/lib/python3.12/site-packages/airflow/utils/cli.py", line 115, in wrapper
    return f(*args, **kwargs)
           ^^^^^^^^^^^^^^^^^^
  File "/home/airflow/.local/lib/python3.12/site-packages/airflow/cli/commands/task_command.py", line 483, in task_run
    task_return_code = _run_task_by_selected_method(args, _dag, ti)
                       ^^^^^^^^^^^^^^^^^^^^^^^^^^^^^^^^^^^^^^^^^^^^
  File "/home/airflow/.local/lib/python3.12/site-packages/airflow/cli/commands/task_command.py", line 256, in _run_task_by_selected_method
    return _run_raw_task(args, ti)
           ^^^^^^^^^^^^^^^^^^^^^^^
  File "/home/airflow/.local/lib/python3.12/site-packages/airflow/cli/commands/task_command.py", line 341, in _run_raw_task
    return ti._run_raw_task(
           ^^^^^^^^^^^^^^^^^
  File "/home/airflow/.local/lib/python3.12/site-packages/airflow/utils/session.py", line 97, in wrapper
    return func(*args, session=session, **kwargs)
           ^^^^^^^^^^^^^^^^^^^^^^^^^^^^^^^^^^^^^^
  File "/home/airflow/.local/lib/python3.12/site-packages/airflow/models/taskinstance.py", line 3004, in _run_raw_task
    return _run_raw_task(
           ^^^^^^^^^^^^^^
  File "/home/airflow/.local/lib/python3.12/site-packages/airflow/models/taskinstance.py", line 273, in _run_raw_task
    TaskInstance._execute_task_with_callbacks(
  File "/home/airflow/.local/lib/python3.12/site-packages/airflow/models/taskinstance.py", line 3158, in _execute_task_with_callbacks
    result = self._execute_task(context, task_orig)
             ^^^^^^^^^^^^^^^^^^^^^^^^^^^^^^^^^^^^^^
  File "/home/airflow/.local/lib/python3.12/site-packages/airflow/models/taskinstance.py", line 3182, in _execute_task
    return _execute_task(self, context, task_orig)
           ^^^^^^^^^^^^^^^^^^^^^^^^^^^^^^^^^^^^^^^
  File "/home/airflow/.local/lib/python3.12/site-packages/airflow/models/taskinstance.py", line 767, in _execute_task
    result = _execute_callable(context=context, **execute_callable_kwargs)
             ^^^^^^^^^^^^^^^^^^^^^^^^^^^^^^^^^^^^^^^^^^^^^^^^^^^^^^^^^^^^^
  File "/home/airflow/.local/lib/python3.12/site-packages/airflow/models/taskinstance.py", line 733, in _execute_callable
    return ExecutionCallableRunner(
           ^^^^^^^^^^^^^^^^^^^^^^^^
  File "/home/airflow/.local/lib/python3.12/site-packages/airflow/utils/operator_helpers.py", line 252, in run
    return self.func(*args, **kwargs)
           ^^^^^^^^^^^^^^^^^^^^^^^^^^
  File "/home/airflow/.local/lib/python3.12/site-packages/airflow/models/baseoperator.py", line 406, in wrapper
    return func(self, *args, **kwargs)
           ^^^^^^^^^^^^^^^^^^^^^^^^^^^
  File "/home/airflow/.local/lib/python3.12/site-packages/airflow/operators/python.py", line 238, in execute
    return_value = self.execute_callable()
                   ^^^^^^^^^^^^^^^^^^^^^^^
  File "/home/airflow/.local/lib/python3.12/site-packages/airflow/operators/python.py", line 256, in execute_callable
    return runner.run(*self.op_args, **self.op_kwargs)
           ^^^^^^^^^^^^^^^^^^^^^^^^^^^^^^^^^^^^^^^^^^^
  File "/home/airflow/.local/lib/python3.12/site-packages/airflow/utils/operator_helpers.py", line 252, in run
    return self.func(*args, **kwargs)
           ^^^^^^^^^^^^^^^^^^^^^^^^^^
  File "/opt/airflow/dags/data_ingestion_to_stg.py", line 25, in load_csv_to_postgres
    raise FileNotFoundError(f"{file_path} tidak ditemukan.")
FileNotFoundError: /opt/***/INPUT/20180509/20180509.sales tidak ditemukan.
[2025-06-10T14:51:05.344+0000] {local_task_job_runner.py:266} INFO - Task exited with return code 1
[2025-06-10T14:51:05.409+0000] {taskinstance.py:3900} INFO - 0 downstream tasks scheduled from follow-on schedule check
[2025-06-10T14:51:05.413+0000] {local_task_job_runner.py:245} INFO - ::endgroup::
