[2025-06-10T14:09:57.714+0000] {local_task_job_runner.py:123} INFO - ::group::Pre task execution logs
[2025-06-10T14:09:57.784+0000] {taskinstance.py:2612} INFO - Dependencies all met for dep_context=non-requeueable deps ti=<TaskInstance: data_ingestion_to_stg.load_sales_20180509 manual__2025-06-10T14:04:40.976039+00:00 [queued]>
[2025-06-10T14:09:57.842+0000] {taskinstance.py:2612} INFO - Dependencies all met for dep_context=requeueable deps ti=<TaskInstance: data_ingestion_to_stg.load_sales_20180509 manual__2025-06-10T14:04:40.976039+00:00 [queued]>
[2025-06-10T14:09:57.844+0000] {taskinstance.py:2865} INFO - Starting attempt 2 of 2
[2025-06-10T14:09:57.925+0000] {taskinstance.py:2888} INFO - Executing <Task(PythonOperator): load_sales_20180509> on 2025-06-10 14:04:40.976039+00:00
[2025-06-10T14:09:57.951+0000] {warnings.py:112} WARNING - /home/***/.local/lib/python3.12/site-packages/***/task/task_runner/standard_task_runner.py:70: DeprecationWarning: This process (pid=529) is multi-threaded, use of fork() may lead to deadlocks in the child.
  pid = os.fork()

[2025-06-10T14:09:57.960+0000] {standard_task_runner.py:72} INFO - Started process 567 to run task
[2025-06-10T14:09:57.959+0000] {standard_task_runner.py:104} INFO - Running: ['***', 'tasks', 'run', 'data_ingestion_to_stg', 'load_sales_20180509', 'manual__2025-06-10T14:04:40.976039+00:00', '--job-id', '131', '--raw', '--subdir', 'DAGS_FOLDER/data_ingestion_to_stg.py', '--cfg-path', '/tmp/tmpsfeuew6a']
[2025-06-10T14:09:57.962+0000] {standard_task_runner.py:105} INFO - Job 131: Subtask load_sales_20180509
[2025-06-10T14:09:58.150+0000] {task_command.py:467} INFO - Running <TaskInstance: data_ingestion_to_stg.load_sales_20180509 manual__2025-06-10T14:04:40.976039+00:00 [running]> on host 615918c75888
[2025-06-10T14:09:58.442+0000] {taskinstance.py:3131} INFO - Exporting env vars: AIRFLOW_CTX_DAG_OWNER='***' AIRFLOW_CTX_DAG_ID='data_ingestion_to_stg' AIRFLOW_CTX_TASK_ID='load_sales_20180509' AIRFLOW_CTX_EXECUTION_DATE='2025-06-10T14:04:40.976039+00:00' AIRFLOW_CTX_TRY_NUMBER='2' AIRFLOW_CTX_DAG_RUN_ID='manual__2025-06-10T14:04:40.976039+00:00'
[2025-06-10T14:09:58.451+0000] {logging_mixin.py:190} INFO - Task instance is in running state
[2025-06-10T14:09:58.454+0000] {logging_mixin.py:190} INFO -  Previous state of the Task instance: queued
[2025-06-10T14:09:58.459+0000] {logging_mixin.py:190} INFO - Current task name:load_sales_20180509 state:running start_date:2025-06-10 14:09:57.792332+00:00
[2025-06-10T14:09:58.459+0000] {logging_mixin.py:190} INFO - Dag name:data_ingestion_to_stg and current dag run status:running
[2025-06-10T14:09:58.466+0000] {taskinstance.py:731} INFO - ::endgroup::
[2025-06-10T14:09:58.469+0000] {taskinstance.py:3310} ERROR - Task failed with exception
Traceback (most recent call last):
  File "/home/airflow/.local/lib/python3.12/site-packages/airflow/models/taskinstance.py", line 767, in _execute_task
    result = _execute_callable(context=context, **execute_callable_kwargs)
             ^^^^^^^^^^^^^^^^^^^^^^^^^^^^^^^^^^^^^^^^^^^^^^^^^^^^^^^^^^^^^
  File "/home/airflow/.local/lib/python3.12/site-packages/airflow/models/taskinstance.py", line 733, in _execute_callable
    return ExecutionCallableRunner(
           ^^^^^^^^^^^^^^^^^^^^^^^^
  File "/home/airflow/.local/lib/python3.12/site-packages/airflow/utils/operator_helpers.py", line 252, in run
    return self.func(*args, **kwargs)
           ^^^^^^^^^^^^^^^^^^^^^^^^^^
  File "/home/airflow/.local/lib/python3.12/site-packages/airflow/models/baseoperator.py", line 406, in wrapper
    return func(self, *args, **kwargs)
           ^^^^^^^^^^^^^^^^^^^^^^^^^^^
  File "/home/airflow/.local/lib/python3.12/site-packages/airflow/operators/python.py", line 238, in execute
    return_value = self.execute_callable()
                   ^^^^^^^^^^^^^^^^^^^^^^^
  File "/home/airflow/.local/lib/python3.12/site-packages/airflow/operators/python.py", line 256, in execute_callable
    return runner.run(*self.op_args, **self.op_kwargs)
           ^^^^^^^^^^^^^^^^^^^^^^^^^^^^^^^^^^^^^^^^^^^
  File "/home/airflow/.local/lib/python3.12/site-packages/airflow/utils/operator_helpers.py", line 252, in run
    return self.func(*args, **kwargs)
           ^^^^^^^^^^^^^^^^^^^^^^^^^^
  File "/opt/airflow/dags/data_ingestion_to_stg.py", line 25, in load_csv_to_postgres
    raise FileNotFoundError(f"{file_path} tidak ditemukan.")
FileNotFoundError: C:/DNA/data-warehouse-project/INPUT/20180509/20180509.sales tidak ditemukan.
[2025-06-10T14:09:58.496+0000] {logging_mixin.py:190} INFO - Task instance in failure state
[2025-06-10T14:09:58.498+0000] {logging_mixin.py:190} INFO - Task start:2025-06-10 14:09:57.792332+00:00 end:2025-06-10 14:09:58.495945+00:00 duration:0.703613
[2025-06-10T14:09:58.501+0000] {logging_mixin.py:190} INFO - Task:<Task(PythonOperator): load_sales_20180509> dag:<DAG: data_ingestion_to_stg> dagrun:<DagRun data_ingestion_to_stg @ 2025-06-10 14:04:40.976039+00:00: manual__2025-06-10T14:04:40.976039+00:00, state:running, queued_at: 2025-06-10 14:04:40.996621+00:00. externally triggered: True>
[2025-06-10T14:09:58.502+0000] {logging_mixin.py:190} INFO - Failure caused by C:/DNA/data-warehouse-project/INPUT/20180509/20180509.sales tidak ditemukan.
[2025-06-10T14:09:58.503+0000] {taskinstance.py:1225} INFO - Marking task as FAILED. dag_id=data_ingestion_to_stg, task_id=load_sales_20180509, run_id=manual__2025-06-10T14:04:40.976039+00:00, execution_date=20250610T140440, start_date=20250610T140957, end_date=20250610T140958
[2025-06-10T14:09:58.538+0000] {taskinstance.py:340} INFO - ::group::Post task execution logs
[2025-06-10T14:09:58.540+0000] {standard_task_runner.py:124} ERROR - Failed to execute job 131 for task load_sales_20180509 (C:/DNA/data-warehouse-project/INPUT/20180509/20180509.sales tidak ditemukan.; 567)
Traceback (most recent call last):
  File "/home/airflow/.local/lib/python3.12/site-packages/airflow/task/task_runner/standard_task_runner.py", line 117, in _start_by_fork
    ret = args.func(args, dag=self.dag)
          ^^^^^^^^^^^^^^^^^^^^^^^^^^^^^
  File "/home/airflow/.local/lib/python3.12/site-packages/airflow/cli/cli_config.py", line 49, in command
    return func(*args, **kwargs)
           ^^^^^^^^^^^^^^^^^^^^^
  File "/home/airflow/.local/lib/python3.12/site-packages/airflow/utils/cli.py", line 115, in wrapper
    return f(*args, **kwargs)
           ^^^^^^^^^^^^^^^^^^
  File "/home/airflow/.local/lib/python3.12/site-packages/airflow/cli/commands/task_command.py", line 483, in task_run
    task_return_code = _run_task_by_selected_method(args, _dag, ti)
                       ^^^^^^^^^^^^^^^^^^^^^^^^^^^^^^^^^^^^^^^^^^^^
  File "/home/airflow/.local/lib/python3.12/site-packages/airflow/cli/commands/task_command.py", line 256, in _run_task_by_selected_method
    return _run_raw_task(args, ti)
           ^^^^^^^^^^^^^^^^^^^^^^^
  File "/home/airflow/.local/lib/python3.12/site-packages/airflow/cli/commands/task_command.py", line 341, in _run_raw_task
    return ti._run_raw_task(
           ^^^^^^^^^^^^^^^^^
  File "/home/airflow/.local/lib/python3.12/site-packages/airflow/utils/session.py", line 97, in wrapper
    return func(*args, session=session, **kwargs)
           ^^^^^^^^^^^^^^^^^^^^^^^^^^^^^^^^^^^^^^
  File "/home/airflow/.local/lib/python3.12/site-packages/airflow/models/taskinstance.py", line 3004, in _run_raw_task
    return _run_raw_task(
           ^^^^^^^^^^^^^^
  File "/home/airflow/.local/lib/python3.12/site-packages/airflow/models/taskinstance.py", line 273, in _run_raw_task
    TaskInstance._execute_task_with_callbacks(
  File "/home/airflow/.local/lib/python3.12/site-packages/airflow/models/taskinstance.py", line 3158, in _execute_task_with_callbacks
    result = self._execute_task(context, task_orig)
             ^^^^^^^^^^^^^^^^^^^^^^^^^^^^^^^^^^^^^^
  File "/home/airflow/.local/lib/python3.12/site-packages/airflow/models/taskinstance.py", line 3182, in _execute_task
    return _execute_task(self, context, task_orig)
           ^^^^^^^^^^^^^^^^^^^^^^^^^^^^^^^^^^^^^^^
  File "/home/airflow/.local/lib/python3.12/site-packages/airflow/models/taskinstance.py", line 767, in _execute_task
    result = _execute_callable(context=context, **execute_callable_kwargs)
             ^^^^^^^^^^^^^^^^^^^^^^^^^^^^^^^^^^^^^^^^^^^^^^^^^^^^^^^^^^^^^
  File "/home/airflow/.local/lib/python3.12/site-packages/airflow/models/taskinstance.py", line 733, in _execute_callable
    return ExecutionCallableRunner(
           ^^^^^^^^^^^^^^^^^^^^^^^^
  File "/home/airflow/.local/lib/python3.12/site-packages/airflow/utils/operator_helpers.py", line 252, in run
    return self.func(*args, **kwargs)
           ^^^^^^^^^^^^^^^^^^^^^^^^^^
  File "/home/airflow/.local/lib/python3.12/site-packages/airflow/models/baseoperator.py", line 406, in wrapper
    return func(self, *args, **kwargs)
           ^^^^^^^^^^^^^^^^^^^^^^^^^^^
  File "/home/airflow/.local/lib/python3.12/site-packages/airflow/operators/python.py", line 238, in execute
    return_value = self.execute_callable()
                   ^^^^^^^^^^^^^^^^^^^^^^^
  File "/home/airflow/.local/lib/python3.12/site-packages/airflow/operators/python.py", line 256, in execute_callable
    return runner.run(*self.op_args, **self.op_kwargs)
           ^^^^^^^^^^^^^^^^^^^^^^^^^^^^^^^^^^^^^^^^^^^
  File "/home/airflow/.local/lib/python3.12/site-packages/airflow/utils/operator_helpers.py", line 252, in run
    return self.func(*args, **kwargs)
           ^^^^^^^^^^^^^^^^^^^^^^^^^^
  File "/opt/airflow/dags/data_ingestion_to_stg.py", line 25, in load_csv_to_postgres
    raise FileNotFoundError(f"{file_path} tidak ditemukan.")
FileNotFoundError: C:/DNA/data-warehouse-project/INPUT/20180509/20180509.sales tidak ditemukan.
[2025-06-10T14:09:58.602+0000] {local_task_job_runner.py:266} INFO - Task exited with return code 1
[2025-06-10T14:09:58.644+0000] {taskinstance.py:3900} INFO - 0 downstream tasks scheduled from follow-on schedule check
[2025-06-10T14:09:58.647+0000] {local_task_job_runner.py:245} INFO - ::endgroup::
