[2025-06-10T13:48:11.395+0000] {local_task_job_runner.py:123} INFO - ::group::Pre task execution logs
[2025-06-10T13:48:11.479+0000] {taskinstance.py:2612} INFO - Dependencies all met for dep_context=non-requeueable deps ti=<TaskInstance: data_ingestion_to_stg.load_countries_20180509 manual__2025-06-10T13:47:56.252993+00:00 [queued]>
[2025-06-10T13:48:11.515+0000] {taskinstance.py:2612} INFO - Dependencies all met for dep_context=requeueable deps ti=<TaskInstance: data_ingestion_to_stg.load_countries_20180509 manual__2025-06-10T13:47:56.252993+00:00 [queued]>
[2025-06-10T13:48:11.524+0000] {taskinstance.py:2865} INFO - Starting attempt 1 of 2
[2025-06-10T13:48:11.681+0000] {taskinstance.py:2888} INFO - Executing <Task(PythonOperator): load_countries_20180509> on 2025-06-10 13:47:56.252993+00:00
[2025-06-10T13:48:11.761+0000] {warnings.py:112} WARNING - /home/***/.local/lib/python3.12/site-packages/***/task/task_runner/standard_task_runner.py:70: DeprecationWarning: This process (pid=77) is multi-threaded, use of fork() may lead to deadlocks in the child.
  pid = os.fork()

[2025-06-10T13:48:11.785+0000] {standard_task_runner.py:72} INFO - Started process 103 to run task
[2025-06-10T13:48:11.769+0000] {standard_task_runner.py:104} INFO - Running: ['***', 'tasks', 'run', 'data_ingestion_to_stg', 'load_countries_20180509', 'manual__2025-06-10T13:47:56.252993+00:00', '--job-id', '25', '--raw', '--subdir', 'DAGS_FOLDER/data_ingestion_to_stg.py', '--cfg-path', '/tmp/tmpq38v3qnb']
[2025-06-10T13:48:11.788+0000] {standard_task_runner.py:105} INFO - Job 25: Subtask load_countries_20180509
[2025-06-10T13:48:12.054+0000] {task_command.py:467} INFO - Running <TaskInstance: data_ingestion_to_stg.load_countries_20180509 manual__2025-06-10T13:47:56.252993+00:00 [running]> on host be33e6a412c8
[2025-06-10T13:48:12.515+0000] {taskinstance.py:3131} INFO - Exporting env vars: AIRFLOW_CTX_DAG_OWNER='***' AIRFLOW_CTX_DAG_ID='data_ingestion_to_stg' AIRFLOW_CTX_TASK_ID='load_countries_20180509' AIRFLOW_CTX_EXECUTION_DATE='2025-06-10T13:47:56.252993+00:00' AIRFLOW_CTX_TRY_NUMBER='1' AIRFLOW_CTX_DAG_RUN_ID='manual__2025-06-10T13:47:56.252993+00:00'
[2025-06-10T13:48:12.521+0000] {logging_mixin.py:190} INFO - Task instance is in running state
[2025-06-10T13:48:12.522+0000] {logging_mixin.py:190} INFO -  Previous state of the Task instance: queued
[2025-06-10T13:48:12.523+0000] {logging_mixin.py:190} INFO - Current task name:load_countries_20180509 state:running start_date:2025-06-10 13:48:11.482112+00:00
[2025-06-10T13:48:12.524+0000] {logging_mixin.py:190} INFO - Dag name:data_ingestion_to_stg and current dag run status:running
[2025-06-10T13:48:12.525+0000] {taskinstance.py:731} INFO - ::endgroup::
[2025-06-10T13:48:12.527+0000] {taskinstance.py:3310} ERROR - Task failed with exception
Traceback (most recent call last):
  File "/home/airflow/.local/lib/python3.12/site-packages/airflow/models/taskinstance.py", line 767, in _execute_task
    result = _execute_callable(context=context, **execute_callable_kwargs)
             ^^^^^^^^^^^^^^^^^^^^^^^^^^^^^^^^^^^^^^^^^^^^^^^^^^^^^^^^^^^^^
  File "/home/airflow/.local/lib/python3.12/site-packages/airflow/models/taskinstance.py", line 733, in _execute_callable
    return ExecutionCallableRunner(
           ^^^^^^^^^^^^^^^^^^^^^^^^
  File "/home/airflow/.local/lib/python3.12/site-packages/airflow/utils/operator_helpers.py", line 252, in run
    return self.func(*args, **kwargs)
           ^^^^^^^^^^^^^^^^^^^^^^^^^^
  File "/home/airflow/.local/lib/python3.12/site-packages/airflow/models/baseoperator.py", line 406, in wrapper
    return func(self, *args, **kwargs)
           ^^^^^^^^^^^^^^^^^^^^^^^^^^^
  File "/home/airflow/.local/lib/python3.12/site-packages/airflow/operators/python.py", line 238, in execute
    return_value = self.execute_callable()
                   ^^^^^^^^^^^^^^^^^^^^^^^
  File "/home/airflow/.local/lib/python3.12/site-packages/airflow/operators/python.py", line 256, in execute_callable
    return runner.run(*self.op_args, **self.op_kwargs)
           ^^^^^^^^^^^^^^^^^^^^^^^^^^^^^^^^^^^^^^^^^^^
  File "/home/airflow/.local/lib/python3.12/site-packages/airflow/utils/operator_helpers.py", line 252, in run
    return self.func(*args, **kwargs)
           ^^^^^^^^^^^^^^^^^^^^^^^^^^
  File "/opt/airflow/dags/data_ingestion_to_stg.py", line 25, in load_csv_to_postgres
    raise FileNotFoundError(f"{file_path} tidak ditemukan.")
FileNotFoundError: C:/DNA/data-warehouse-project/INPUT/20180509/20180509.countries tidak ditemukan.
[2025-06-10T13:48:12.604+0000] {logging_mixin.py:190} INFO - Task instance in failure state
[2025-06-10T13:48:12.617+0000] {logging_mixin.py:190} INFO - Task start:2025-06-10 13:48:11.482112+00:00 end:2025-06-10 13:48:12.601338+00:00 duration:1.119226
[2025-06-10T13:48:12.626+0000] {logging_mixin.py:190} INFO - Task:<Task(PythonOperator): load_countries_20180509> dag:<DAG: data_ingestion_to_stg> dagrun:<DagRun data_ingestion_to_stg @ 2025-06-10 13:47:56.252993+00:00: manual__2025-06-10T13:47:56.252993+00:00, state:running, queued_at: 2025-06-10 13:47:56.290074+00:00. externally triggered: True>
[2025-06-10T13:48:12.638+0000] {logging_mixin.py:190} INFO - Failure caused by C:/DNA/data-warehouse-project/INPUT/20180509/20180509.countries tidak ditemukan.
[2025-06-10T13:48:12.641+0000] {taskinstance.py:1225} INFO - Marking task as UP_FOR_RETRY. dag_id=data_ingestion_to_stg, task_id=load_countries_20180509, run_id=manual__2025-06-10T13:47:56.252993+00:00, execution_date=20250610T134756, start_date=20250610T134811, end_date=20250610T134812
[2025-06-10T13:48:12.716+0000] {taskinstance.py:340} INFO - ::group::Post task execution logs
[2025-06-10T13:48:12.721+0000] {standard_task_runner.py:124} ERROR - Failed to execute job 25 for task load_countries_20180509 (C:/DNA/data-warehouse-project/INPUT/20180509/20180509.countries tidak ditemukan.; 103)
Traceback (most recent call last):
  File "/home/airflow/.local/lib/python3.12/site-packages/airflow/task/task_runner/standard_task_runner.py", line 117, in _start_by_fork
    ret = args.func(args, dag=self.dag)
          ^^^^^^^^^^^^^^^^^^^^^^^^^^^^^
  File "/home/airflow/.local/lib/python3.12/site-packages/airflow/cli/cli_config.py", line 49, in command
    return func(*args, **kwargs)
           ^^^^^^^^^^^^^^^^^^^^^
  File "/home/airflow/.local/lib/python3.12/site-packages/airflow/utils/cli.py", line 115, in wrapper
    return f(*args, **kwargs)
           ^^^^^^^^^^^^^^^^^^
  File "/home/airflow/.local/lib/python3.12/site-packages/airflow/cli/commands/task_command.py", line 483, in task_run
    task_return_code = _run_task_by_selected_method(args, _dag, ti)
                       ^^^^^^^^^^^^^^^^^^^^^^^^^^^^^^^^^^^^^^^^^^^^
  File "/home/airflow/.local/lib/python3.12/site-packages/airflow/cli/commands/task_command.py", line 256, in _run_task_by_selected_method
    return _run_raw_task(args, ti)
           ^^^^^^^^^^^^^^^^^^^^^^^
  File "/home/airflow/.local/lib/python3.12/site-packages/airflow/cli/commands/task_command.py", line 341, in _run_raw_task
    return ti._run_raw_task(
           ^^^^^^^^^^^^^^^^^
  File "/home/airflow/.local/lib/python3.12/site-packages/airflow/utils/session.py", line 97, in wrapper
    return func(*args, session=session, **kwargs)
           ^^^^^^^^^^^^^^^^^^^^^^^^^^^^^^^^^^^^^^
  File "/home/airflow/.local/lib/python3.12/site-packages/airflow/models/taskinstance.py", line 3004, in _run_raw_task
    return _run_raw_task(
           ^^^^^^^^^^^^^^
  File "/home/airflow/.local/lib/python3.12/site-packages/airflow/models/taskinstance.py", line 273, in _run_raw_task
    TaskInstance._execute_task_with_callbacks(
  File "/home/airflow/.local/lib/python3.12/site-packages/airflow/models/taskinstance.py", line 3158, in _execute_task_with_callbacks
    result = self._execute_task(context, task_orig)
             ^^^^^^^^^^^^^^^^^^^^^^^^^^^^^^^^^^^^^^
  File "/home/airflow/.local/lib/python3.12/site-packages/airflow/models/taskinstance.py", line 3182, in _execute_task
    return _execute_task(self, context, task_orig)
           ^^^^^^^^^^^^^^^^^^^^^^^^^^^^^^^^^^^^^^^
  File "/home/airflow/.local/lib/python3.12/site-packages/airflow/models/taskinstance.py", line 767, in _execute_task
    result = _execute_callable(context=context, **execute_callable_kwargs)
             ^^^^^^^^^^^^^^^^^^^^^^^^^^^^^^^^^^^^^^^^^^^^^^^^^^^^^^^^^^^^^
  File "/home/airflow/.local/lib/python3.12/site-packages/airflow/models/taskinstance.py", line 733, in _execute_callable
    return ExecutionCallableRunner(
           ^^^^^^^^^^^^^^^^^^^^^^^^
  File "/home/airflow/.local/lib/python3.12/site-packages/airflow/utils/operator_helpers.py", line 252, in run
    return self.func(*args, **kwargs)
           ^^^^^^^^^^^^^^^^^^^^^^^^^^
  File "/home/airflow/.local/lib/python3.12/site-packages/airflow/models/baseoperator.py", line 406, in wrapper
    return func(self, *args, **kwargs)
           ^^^^^^^^^^^^^^^^^^^^^^^^^^^
  File "/home/airflow/.local/lib/python3.12/site-packages/airflow/operators/python.py", line 238, in execute
    return_value = self.execute_callable()
                   ^^^^^^^^^^^^^^^^^^^^^^^
  File "/home/airflow/.local/lib/python3.12/site-packages/airflow/operators/python.py", line 256, in execute_callable
    return runner.run(*self.op_args, **self.op_kwargs)
           ^^^^^^^^^^^^^^^^^^^^^^^^^^^^^^^^^^^^^^^^^^^
  File "/home/airflow/.local/lib/python3.12/site-packages/airflow/utils/operator_helpers.py", line 252, in run
    return self.func(*args, **kwargs)
           ^^^^^^^^^^^^^^^^^^^^^^^^^^
  File "/opt/airflow/dags/data_ingestion_to_stg.py", line 25, in load_csv_to_postgres
    raise FileNotFoundError(f"{file_path} tidak ditemukan.")
FileNotFoundError: C:/DNA/data-warehouse-project/INPUT/20180509/20180509.countries tidak ditemukan.
[2025-06-10T13:48:12.872+0000] {local_task_job_runner.py:266} INFO - Task exited with return code 1
[2025-06-10T13:48:12.933+0000] {local_task_job_runner.py:245} INFO - ::endgroup::
